/Library/Frameworks/Python.framework/Versions/3.7/lib/python3.7/site-packages/pytorch_lightning/loggers/wandb.py:396: UserWarning: There is a wandb run already in progress and newly created instances of `WandbLogger` will reuse this run. If this is not desired, call `wandb.finish()` before instantiating `WandbLogger`.
  "There is a wandb run already in progress and newly created instances of `WandbLogger` will reuse"
Global seed set to 23
GPU available: False, used: False
TPU available: False, using: 0 TPU cores
IPU available: False, using: 0 IPUs
HPU available: False, using: 0 HPUs
  | Name                 | Type               | Params
------------------------------------------------------------
0 | resnet               | ResNet             | 14.4 M
1 | fc1                  | Linear             | 15.4 K
2 | fc2                  | Linear             | 7.7 K
3 | fc3                  | Linear             | 33
4 | train_macro_accuracy | MulticlassAccuracy | 0
5 | val_macro_accuracy   | MulticlassAccuracy | 0
6 | test_macro_accuracy  | MulticlassAccuracy | 0
7 | train_accuracy       | MulticlassAccuracy | 0
8 | val_accuracy         | MulticlassAccuracy | 0
9 | test_accuracy        | MulticlassAccuracy | 0
------------------------------------------------------------
14.4 M    Trainable params
0         Non-trainable params
14.4 M    Total params
57.764    Total estimated model params size (MB)
/Library/Frameworks/Python.framework/Versions/3.7/lib/python3.7/site-packages/pytorch_lightning/trainer/connectors/data_connector.py:229: PossibleUserWarning: The dataloader, val_dataloader 0, does not have many workers which may be a bottleneck. Consider increasing the value of the `num_workers` argument` (try 4 which is the number of cpus on this machine) in the `DataLoader` init to improve performance.
  category=PossibleUserWarning,
Train dataset length: 424
Validation dataset length: 142
Sanity Checking: 0it [00:00, ?it/s]
Traceback (most recent call last):
  File "main.py", line 215, in <module>
    main_multimodal(wandb, wandb_logger)
  File "main.py", line 85, in main_multimodal
    trainer.fit(model=model, train_dataloaders=train_loader, val_dataloaders=val_loader)
  File "/Library/Frameworks/Python.framework/Versions/3.7/lib/python3.7/site-packages/pytorch_lightning/trainer/trainer.py", line 609, in fit
    self, self._fit_impl, model, train_dataloaders, val_dataloaders, datamodule, ckpt_path
  File "/Library/Frameworks/Python.framework/Versions/3.7/lib/python3.7/site-packages/pytorch_lightning/trainer/call.py", line 38, in _call_and_handle_interrupt
    return trainer_fn(*args, **kwargs)
  File "/Library/Frameworks/Python.framework/Versions/3.7/lib/python3.7/site-packages/pytorch_lightning/trainer/trainer.py", line 650, in _fit_impl
    self._run(model, ckpt_path=self.ckpt_path)
  File "/Library/Frameworks/Python.framework/Versions/3.7/lib/python3.7/site-packages/pytorch_lightning/trainer/trainer.py", line 1112, in _run
    results = self._run_stage()
  File "/Library/Frameworks/Python.framework/Versions/3.7/lib/python3.7/site-packages/pytorch_lightning/trainer/trainer.py", line 1191, in _run_stage
    self._run_train()
  File "/Library/Frameworks/Python.framework/Versions/3.7/lib/python3.7/site-packages/pytorch_lightning/trainer/trainer.py", line 1204, in _run_train
    self._run_sanity_check()
  File "/Library/Frameworks/Python.framework/Versions/3.7/lib/python3.7/site-packages/pytorch_lightning/trainer/trainer.py", line 1276, in _run_sanity_check
    val_loop.run()
  File "/Library/Frameworks/Python.framework/Versions/3.7/lib/python3.7/site-packages/pytorch_lightning/loops/loop.py", line 199, in run
    self.advance(*args, **kwargs)
  File "/Library/Frameworks/Python.framework/Versions/3.7/lib/python3.7/site-packages/pytorch_lightning/loops/dataloader/evaluation_loop.py", line 152, in advance
    dl_outputs = self.epoch_loop.run(self._data_fetcher, dl_max_batches, kwargs)
  File "/Library/Frameworks/Python.framework/Versions/3.7/lib/python3.7/site-packages/pytorch_lightning/loops/loop.py", line 199, in run
    self.advance(*args, **kwargs)
  File "/Library/Frameworks/Python.framework/Versions/3.7/lib/python3.7/site-packages/pytorch_lightning/loops/epoch/evaluation_epoch_loop.py", line 121, in advance
    batch = next(data_fetcher)
  File "/Library/Frameworks/Python.framework/Versions/3.7/lib/python3.7/site-packages/pytorch_lightning/utilities/fetching.py", line 184, in __next__
    return self.fetching_function()
  File "/Library/Frameworks/Python.framework/Versions/3.7/lib/python3.7/site-packages/pytorch_lightning/utilities/fetching.py", line 265, in fetching_function
    self._fetch_next_batch(self.dataloader_iter)
  File "/Library/Frameworks/Python.framework/Versions/3.7/lib/python3.7/site-packages/pytorch_lightning/utilities/fetching.py", line 280, in _fetch_next_batch
    batch = next(iterator)
  File "/Library/Frameworks/Python.framework/Versions/3.7/lib/python3.7/site-packages/torch/utils/data/dataloader.py", line 628, in __next__
    data = self._next_data()
  File "/Library/Frameworks/Python.framework/Versions/3.7/lib/python3.7/site-packages/torch/utils/data/dataloader.py", line 1333, in _next_data
    return self._process_data(data)
  File "/Library/Frameworks/Python.framework/Versions/3.7/lib/python3.7/site-packages/torch/utils/data/dataloader.py", line 1359, in _process_data
    data.reraise()
  File "/Library/Frameworks/Python.framework/Versions/3.7/lib/python3.7/site-packages/torch/_utils.py", line 543, in reraise
    raise exception
FileNotFoundError: Caught FileNotFoundError in DataLoader worker process 0.
Original Traceback (most recent call last):
  File "/Library/Frameworks/Python.framework/Versions/3.7/lib/python3.7/site-packages/nibabel/loadsave.py", line 90, in load
    stat_result = os.stat(filename)
FileNotFoundError: [Errno 2] No such file or directory: '/Users/MaryFetter/Documents/GitHub/NCANDA_Contrastive/NCANDA_T1_T2/T1_small/NCANDA_S00125.nii'
During handling of the above exception, another exception occurred:
Traceback (most recent call last):
  File "/Library/Frameworks/Python.framework/Versions/3.7/lib/python3.7/site-packages/torch/utils/data/_utils/worker.py", line 302, in _worker_loop
    data = fetcher.fetch(index)
  File "/Library/Frameworks/Python.framework/Versions/3.7/lib/python3.7/site-packages/torch/utils/data/_utils/fetch.py", line 58, in fetch
    data = [self.dataset[idx] for idx in possibly_batched_index]
  File "/Library/Frameworks/Python.framework/Versions/3.7/lib/python3.7/site-packages/torch/utils/data/_utils/fetch.py", line 58, in <listcomp>
    data = [self.dataset[idx] for idx in possibly_batched_index]
  File "/Users/MaryFetter/Documents/GitHub/NCANDA_Contrastive/multimodal_dataset.py", line 80, in __getitem__
    image = nib.load(image_path)
  File "/Library/Frameworks/Python.framework/Versions/3.7/lib/python3.7/site-packages/nibabel/loadsave.py", line 92, in load
    raise FileNotFoundError(f"No such file or no access: '{filename}'")
FileNotFoundError: No such file or no access: '/Users/MaryFetter/Documents/GitHub/NCANDA_Contrastive/NCANDA_T1_T2/T1_small/NCANDA_S00125.nii'